Traceback (most recent call last):
  File "/home/yyy/.local/lib/python3.6/site-packages/_pytest/config/__init__.py", line 495, in _importconftest
    return self._conftestpath2mod[key]
KeyError: PosixPath('/home/yyy/checkerfile/Type/master/pyttracer/pygal-master/pygal/test/conftest.py')

During handling of the above exception, another exception occurred:

Traceback (most recent call last):
  File "/home/yyy/checkerfile/Type/master/pyttracer/pyttracer/pyinspector.py", line 44, in inspect_line
    self.analyzer.handle_line(frame, event, arg)
  File "/home/yyy/checkerfile/Type/master/pyttracer/pyttracer/pytracer.py", line 301, in handle_line
    shadower.shadow(node)
  File "/home/yyy/checkerfile/Type/master/pyttracer/pyttracer/shadower.py", line 14, in shadow
    shadow_func(node)
  File "/home/yyy/checkerfile/Type/master/pyttracer/pyttracer/shadower.py", line 35, in shadow_assign
    self.shadow(tgt)
  File "/home/yyy/checkerfile/Type/master/pyttracer/pyttracer/shadower.py", line 14, in shadow
    shadow_func(node)
  File "/home/yyy/checkerfile/Type/master/pyttracer/pyttracer/shadower.py", line 213, in shadow_attribute
    self.shadow(node.value)
  File "/home/yyy/checkerfile/Type/master/pyttracer/pyttracer/shadower.py", line 14, in shadow
    shadow_func(node)
  File "/home/yyy/checkerfile/Type/master/pyttracer/pyttracer/shadower.py", line 259, in shadow_name
    typename = getlivetypename(self.frame, node.id)
  File "/home/yyy/checkerfile/Type/master/pyttracer/pyttracer/utils.py", line 90, in getlivetypename
    livetype = getlivetype(frame, name)
  File "/home/yyy/checkerfile/Type/master/pyttracer/pyttracer/utils.py", line 78, in getlivetype
    return getlivetype_from_obj(liveobj)
  File "/home/yyy/checkerfile/Type/master/pyttracer/pyttracer/utils.py", line 83, in getlivetype_from_obj
    return obj.__class__
  File "/home/yyy/checkerfile/Type/master/pyttracer/pygal-master/pygal/etree.py", line 50, in __getattribute__
    return object.__getattribute__(self._etree, attr)
  File "/home/yyy/checkerfile/Type/master/pyttracer/pygal-master/pygal/etree.py", line 50, in __getattribute__
    return object.__getattribute__(self._etree, attr)
  File "/home/yyy/checkerfile/Type/master/pyttracer/pygal-master/pygal/etree.py", line 50, in __getattribute__
    return object.__getattribute__(self._etree, attr)
  [Previous line repeated 3288 more times]
RecursionError: maximum recursion depth exceeded
Traceback (most recent call last):
  File "/home/yyy/.local/lib/python3.6/site-packages/_pytest/config/__init__.py", line 495, in _importconftest
    return self._conftestpath2mod[key]
KeyError: PosixPath('/home/yyy/checkerfile/Type/master/pyttracer/pygal-master/pygal/test/conftest.py')

During handling of the above exception, another exception occurred:

Traceback (most recent call last):
  File "/home/yyy/checkerfile/Type/master/pyttracer/pyttracer/pyinspector.py", line 44, in inspect_line
    self.analyzer.handle_line(frame, event, arg)
  File "/home/yyy/checkerfile/Type/master/pyttracer/pyttracer/pytracer.py", line 301, in handle_line
    shadower.shadow(node)
  File "/home/yyy/checkerfile/Type/master/pyttracer/pyttracer/shadower.py", line 14, in shadow
    shadow_func(node)
  File "/home/yyy/checkerfile/Type/master/pyttracer/pyttracer/shadower.py", line 35, in shadow_assign
    self.shadow(tgt)
  File "/home/yyy/checkerfile/Type/master/pyttracer/pyttracer/shadower.py", line 14, in shadow
    shadow_func(node)
  File "/home/yyy/checkerfile/Type/master/pyttracer/pyttracer/shadower.py", line 213, in shadow_attribute
    self.shadow(node.value)
  File "/home/yyy/checkerfile/Type/master/pyttracer/pyttracer/shadower.py", line 14, in shadow
    shadow_func(node)
  File "/home/yyy/checkerfile/Type/master/pyttracer/pyttracer/shadower.py", line 259, in shadow_name
    typename = getlivetypename(self.frame, node.id)
  File "/home/yyy/checkerfile/Type/master/pyttracer/pyttracer/utils.py", line 90, in getlivetypename
    livetype = getlivetype(frame, name)
  File "/home/yyy/checkerfile/Type/master/pyttracer/pyttracer/utils.py", line 78, in getlivetype
    return getlivetype_from_obj(liveobj)
  File "/home/yyy/checkerfile/Type/master/pyttracer/pyttracer/utils.py", line 83, in getlivetype_from_obj
    return obj.__class__
  File "/home/yyy/checkerfile/Type/master/pyttracer/pygal-master/pygal/etree.py", line 50, in __getattribute__
    return object.__getattribute__(self._etree, attr)
  File "/home/yyy/checkerfile/Type/master/pyttracer/pygal-master/pygal/etree.py", line 50, in __getattribute__
    return object.__getattribute__(self._etree, attr)
  File "/home/yyy/checkerfile/Type/master/pyttracer/pygal-master/pygal/etree.py", line 50, in __getattribute__
    return object.__getattribute__(self._etree, attr)
  [Previous line repeated 3288 more times]
RecursionError: maximum recursion depth exceeded
Traceback (most recent call last):
  File "/home/yyy/.local/lib/python3.6/site-packages/_pytest/config/__init__.py", line 495, in _importconftest
    return self._conftestpath2mod[key]
KeyError: PosixPath('/home/yyy/checkerfile/Type/master/pyttracer/pygal-master/pygal/test/conftest.py')

During handling of the above exception, another exception occurred:

Traceback (most recent call last):
  File "/home/yyy/checkerfile/Type/master/pyttracer/pyttracer/pyinspector.py", line 44, in inspect_line
    self.analyzer.handle_line(frame, event, arg)
  File "/home/yyy/checkerfile/Type/master/pyttracer/pyttracer/pytracer.py", line 301, in handle_line
    shadower.shadow(node)
  File "/home/yyy/checkerfile/Type/master/pyttracer/pyttracer/shadower.py", line 14, in shadow
    shadow_func(node)
  File "/home/yyy/checkerfile/Type/master/pyttracer/pyttracer/shadower.py", line 35, in shadow_assign
    self.shadow(tgt)
  File "/home/yyy/checkerfile/Type/master/pyttracer/pyttracer/shadower.py", line 14, in shadow
    shadow_func(node)
  File "/home/yyy/checkerfile/Type/master/pyttracer/pyttracer/shadower.py", line 213, in shadow_attribute
    self.shadow(node.value)
  File "/home/yyy/checkerfile/Type/master/pyttracer/pyttracer/shadower.py", line 14, in shadow
    shadow_func(node)
  File "/home/yyy/checkerfile/Type/master/pyttracer/pyttracer/shadower.py", line 259, in shadow_name
    typename = getlivetypename(self.frame, node.id)
  File "/home/yyy/checkerfile/Type/master/pyttracer/pyttracer/utils.py", line 90, in getlivetypename
    livetype = getlivetype(frame, name)
  File "/home/yyy/checkerfile/Type/master/pyttracer/pyttracer/utils.py", line 78, in getlivetype
    return getlivetype_from_obj(liveobj)
  File "/home/yyy/checkerfile/Type/master/pyttracer/pyttracer/utils.py", line 83, in getlivetype_from_obj
    return obj.__class__
  File "/home/yyy/checkerfile/Type/master/pyttracer/pygal-master/pygal/etree.py", line 50, in __getattribute__
    return object.__getattribute__(self._etree, attr)
  File "/home/yyy/checkerfile/Type/master/pyttracer/pygal-master/pygal/etree.py", line 50, in __getattribute__
    return object.__getattribute__(self._etree, attr)
  File "/home/yyy/checkerfile/Type/master/pyttracer/pygal-master/pygal/etree.py", line 50, in __getattribute__
    return object.__getattribute__(self._etree, attr)
  [Previous line repeated 3288 more times]
RecursionError: maximum recursion depth exceeded
Traceback (most recent call last):
  File "/home/yyy/.local/lib/python3.6/site-packages/_pytest/config/__init__.py", line 495, in _importconftest
    return self._conftestpath2mod[key]
KeyError: PosixPath('/home/yyy/checkerfile/Type/master/pyttracer/pygal-master/pygal/test/conftest.py')

During handling of the above exception, another exception occurred:

Traceback (most recent call last):
  File "/home/yyy/checkerfile/Type/master/pyttracer/pyttracer/pyinspector.py", line 44, in inspect_line
    self.analyzer.handle_line(frame, event, arg)
  File "/home/yyy/checkerfile/Type/master/pyttracer/pyttracer/pytracer.py", line 301, in handle_line
    shadower.shadow(node)
  File "/home/yyy/checkerfile/Type/master/pyttracer/pyttracer/shadower.py", line 14, in shadow
    shadow_func(node)
  File "/home/yyy/checkerfile/Type/master/pyttracer/pyttracer/shadower.py", line 35, in shadow_assign
    self.shadow(tgt)
  File "/home/yyy/checkerfile/Type/master/pyttracer/pyttracer/shadower.py", line 14, in shadow
    shadow_func(node)
  File "/home/yyy/checkerfile/Type/master/pyttracer/pyttracer/shadower.py", line 213, in shadow_attribute
    self.shadow(node.value)
  File "/home/yyy/checkerfile/Type/master/pyttracer/pyttracer/shadower.py", line 14, in shadow
    shadow_func(node)
  File "/home/yyy/checkerfile/Type/master/pyttracer/pyttracer/shadower.py", line 259, in shadow_name
    typename = getlivetypename(self.frame, node.id)
  File "/home/yyy/checkerfile/Type/master/pyttracer/pyttracer/utils.py", line 90, in getlivetypename
    livetype = getlivetype(frame, name)
  File "/home/yyy/checkerfile/Type/master/pyttracer/pyttracer/utils.py", line 78, in getlivetype
    return getlivetype_from_obj(liveobj)
  File "/home/yyy/checkerfile/Type/master/pyttracer/pyttracer/utils.py", line 83, in getlivetype_from_obj
    return obj.__class__
  File "/home/yyy/checkerfile/Type/master/pyttracer/pygal-master/pygal/etree.py", line 50, in __getattribute__
    return object.__getattribute__(self._etree, attr)
  File "/home/yyy/checkerfile/Type/master/pyttracer/pygal-master/pygal/etree.py", line 50, in __getattribute__
    return object.__getattribute__(self._etree, attr)
  File "/home/yyy/checkerfile/Type/master/pyttracer/pygal-master/pygal/etree.py", line 50, in __getattribute__
    return object.__getattribute__(self._etree, attr)
  [Previous line repeated 3288 more times]
RecursionError: maximum recursion depth exceeded
Traceback (most recent call last):
  File "/home/yyy/.local/lib/python3.6/site-packages/_pytest/config/__init__.py", line 495, in _importconftest
    return self._conftestpath2mod[key]
KeyError: PosixPath('/home/yyy/checkerfile/Type/master/pyttracer/pygal-master/pygal/test/conftest.py')

During handling of the above exception, another exception occurred:

Traceback (most recent call last):
  File "/home/yyy/checkerfile/Type/master/pyttracer/pyttracer/pyinspector.py", line 44, in inspect_line
    self.analyzer.handle_line(frame, event, arg)
  File "/home/yyy/checkerfile/Type/master/pyttracer/pyttracer/pytracer.py", line 301, in handle_line
    shadower.shadow(node)
  File "/home/yyy/checkerfile/Type/master/pyttracer/pyttracer/shadower.py", line 14, in shadow
    shadow_func(node)
  File "/home/yyy/checkerfile/Type/master/pyttracer/pyttracer/shadower.py", line 35, in shadow_assign
    self.shadow(tgt)
  File "/home/yyy/checkerfile/Type/master/pyttracer/pyttracer/shadower.py", line 14, in shadow
    shadow_func(node)
  File "/home/yyy/checkerfile/Type/master/pyttracer/pyttracer/shadower.py", line 213, in shadow_attribute
    self.shadow(node.value)
  File "/home/yyy/checkerfile/Type/master/pyttracer/pyttracer/shadower.py", line 14, in shadow
    shadow_func(node)
  File "/home/yyy/checkerfile/Type/master/pyttracer/pyttracer/shadower.py", line 259, in shadow_name
    typename = getlivetypename(self.frame, node.id)
  File "/home/yyy/checkerfile/Type/master/pyttracer/pyttracer/utils.py", line 90, in getlivetypename
    livetype = getlivetype(frame, name)
  File "/home/yyy/checkerfile/Type/master/pyttracer/pyttracer/utils.py", line 78, in getlivetype
    return getlivetype_from_obj(liveobj)
  File "/home/yyy/checkerfile/Type/master/pyttracer/pyttracer/utils.py", line 83, in getlivetype_from_obj
    return obj.__class__
  File "/home/yyy/checkerfile/Type/master/pyttracer/pygal-master/pygal/etree.py", line 50, in __getattribute__
    return object.__getattribute__(self._etree, attr)
  File "/home/yyy/checkerfile/Type/master/pyttracer/pygal-master/pygal/etree.py", line 50, in __getattribute__
    return object.__getattribute__(self._etree, attr)
  File "/home/yyy/checkerfile/Type/master/pyttracer/pygal-master/pygal/etree.py", line 50, in __getattribute__
    return object.__getattribute__(self._etree, attr)
  [Previous line repeated 3288 more times]
RecursionError: maximum recursion depth exceeded
Traceback (most recent call last):
  File "/home/yyy/.local/lib/python3.6/site-packages/_pytest/config/__init__.py", line 495, in _importconftest
    return self._conftestpath2mod[key]
KeyError: PosixPath('/home/yyy/checkerfile/Type/master/pyttracer/pygal-master/pygal/test/conftest.py')

During handling of the above exception, another exception occurred:

Traceback (most recent call last):
  File "/home/yyy/checkerfile/Type/master/pyttracer/pyttracer/pyinspector.py", line 44, in inspect_line
    self.analyzer.handle_line(frame, event, arg)
  File "/home/yyy/checkerfile/Type/master/pyttracer/pyttracer/pytracer.py", line 301, in handle_line
    shadower.shadow(node)
  File "/home/yyy/checkerfile/Type/master/pyttracer/pyttracer/shadower.py", line 14, in shadow
    shadow_func(node)
  File "/home/yyy/checkerfile/Type/master/pyttracer/pyttracer/shadower.py", line 56, in shadow_if
    self.shadow(node.test)
  File "/home/yyy/checkerfile/Type/master/pyttracer/pyttracer/shadower.py", line 14, in shadow
    shadow_func(node)
  File "/home/yyy/checkerfile/Type/master/pyttracer/pyttracer/shadower.py", line 115, in shadow_boolop
    self.shadow(val)
  File "/home/yyy/checkerfile/Type/master/pyttracer/pyttracer/shadower.py", line 14, in shadow
    shadow_func(node)
  File "/home/yyy/checkerfile/Type/master/pyttracer/pyttracer/shadower.py", line 178, in shadow_compare
    self.shadow(cmptor)
  File "/home/yyy/checkerfile/Type/master/pyttracer/pyttracer/shadower.py", line 14, in shadow
    shadow_func(node)
  File "/home/yyy/checkerfile/Type/master/pyttracer/pyttracer/shadower.py", line 183, in shadow_call
    self.shadow(arg)
  File "/home/yyy/checkerfile/Type/master/pyttracer/pyttracer/shadower.py", line 14, in shadow
    shadow_func(node)
  File "/home/yyy/checkerfile/Type/master/pyttracer/pyttracer/shadower.py", line 259, in shadow_name
    typename = getlivetypename(self.frame, node.id)
  File "/home/yyy/checkerfile/Type/master/pyttracer/pyttracer/utils.py", line 90, in getlivetypename
    livetype = getlivetype(frame, name)
  File "/home/yyy/checkerfile/Type/master/pyttracer/pyttracer/utils.py", line 78, in getlivetype
    return getlivetype_from_obj(liveobj)
  File "/home/yyy/checkerfile/Type/master/pyttracer/pyttracer/utils.py", line 83, in getlivetype_from_obj
    return obj.__class__
  File "/home/yyy/checkerfile/Type/master/pyttracer/pygal-master/pygal/etree.py", line 50, in __getattribute__
    return object.__getattribute__(self._etree, attr)
  File "/home/yyy/checkerfile/Type/master/pyttracer/pygal-master/pygal/etree.py", line 50, in __getattribute__
    return object.__getattribute__(self._etree, attr)
  File "/home/yyy/checkerfile/Type/master/pyttracer/pygal-master/pygal/etree.py", line 50, in __getattribute__
    return object.__getattribute__(self._etree, attr)
  [Previous line repeated 3285 more times]
  File "/home/yyy/checkerfile/Type/master/pyttracer/pygal-master/pygal/etree.py", line 48, in __getattribute__
    if (attr not in object.__getattribute__(self, '__dict__')
RecursionError: maximum recursion depth exceeded while calling a Python object
